---
source: tests/snapshots.rs
expression: output
---
success = false
stdout = ''
stderr = '''
Error:   × break used outside of a loop
   ╭─[control_bad_break.rice:3:3]
 1 │ fn main() {
 2 │   let x = 1 in
 3 |   break
   .   ─────
 4 │ }
   ╰────

'''